<?xml version="1.0" ?>
<!-- =================================================================================== -->
<!-- |    This document was autogenerated by xacro from ardent.xacro                   | -->
<!-- |    EDITING THIS FILE BY HAND IS NOT RECOMMENDED                                 | -->
<!-- =================================================================================== -->
<robot name="ardent" xmlns:xacro="http://www.ros.org/wiki/xacro">
  <!-- <xacro:property name="joint_effort" value ="10000"/>
<xacro:property name="joint_velocity" value ="100"/> -->
  <link name="base_link"/>
  <link name="MP_BODY">
    <inertial>
      <origin xyz="0 0 0"/>
      <mass value="6.8"/>
      <inertia ixx="3.1081800" ixy="-0.25460189" ixz="2.0318174" iyy="6.3787776" iyz="0.16417863" izz="5.3316425"/>
    </inertial>
    <visual>
      <!--origin xyz="-0.0235 0 -0.03525" rpy="0 0 0" /-->
      <origin rpy="0 0 0" xyz="0 0 0"/>
      <geometry>
        <cylinder length="0.17" radius="0.2"/>
        <!--box size="0.102 0.109 0.106" /-->
        <!-- <mesh filename="package://phantomx_description/meshes/body.STL"  scale="1 1 1"/> -->
      </geometry>
      <material name="Orange">
        <color rgba="12 12 12 1.0"/>
      </material>
    </visual>
    <collision>
      <origin rpy="0 0 0" xyz="0 0 0"/>
      <geometry>
        <cylinder length="0.17" radius="0.2"/>
        <!-- <mesh filename="package://phantomx_description/meshes/body_coll.STL"  scale="1 1 1"/> -->
      </geometry>
    </collision>
  </link>
  <joint name="j_ardent_attachment" type="fixed">
    <parent link="base_link"/>
    <child link="MP_BODY"/>
    <origin rpy="0 0 0" xyz="0 0 0"/>
  </joint>
  <!-- <transmission name="t_ardent">
        <type>transmission_interface/SimpleTransmission</type>
        <joint name="j_ardent_attachment">
          <hardwareInterface>hardware_interface/EffortJointInterface</hardwareInterface>    
        </joint>
        <actuator name="j_ardent_attachment">
          <hardwareInterface>hardware_interface/EffortJointInterface</hardwareInterface>
          <mechanicalReduction>1</mechanicalReduction>
        </actuator>
      </transmission> -->
  <link name="coxa_rf">
    <inertial>
      <origin rpy="0 0 0" xyz="0 0 0"/>
      <mass value="0.024357719"/>
      <inertia ixx="0.0051411124" ixy="-0.00057530255" ixz="-0.000024729049" iyy="0.0081915737" iyz="-0.000019223094" izz="0.0011379812"/>
    </inertial>
    <visual>
      <origin rpy="0 0 0" xyz="0 0 0"/>
      <geometry>
        <box size="0.022 0.045 0.0325"/>
        <!--<mesh filename="package://phantomx_description/meshes/connect.STL"  scale="1 1 1"/>-->
      </geometry>
      <material name="Grey">
        <color rgba="0.20 0.20 0.20 1.0"/>
      </material>
    </visual>
    <collision>
      <origin rpy="0 0 0" xyz="0 0 0"/>
      <geometry>
        <box size="0.022 0.045 0.0325"/>
        <!-- <mesh filename="package://phantomx_description/meshes/connect_coll.STL"  scale="1 1 1"/> -->
      </geometry>
    </collision>
  </link>
  <link name="c2_rf">
    <inertial>
      <origin rpy="0 0 0" xyz="0 0 0"/>
      <mass value="0.024357719"/>
      <inertia ixx="0.0051411124" ixy="-0.00057530255" ixz="-0.000024729049" iyy="0.0081915737" iyz="-0.000019223094" izz="0.0011379812"/>
    </inertial>
    <visual>
      <origin rpy="0 0 0" xyz="0 0 0"/>
      <geometry>
        <box size="0.005 0.0325 0.0325"/>
        <!-- <mesh filename="package://phantomx_description/meshes/connect.STL"  scale="1 1 1"/>-->
      </geometry>
      <material name="Orange">
        <color rgba="12 12 12 1.0"/>
      </material>
    </visual>
    <collision>
      <origin rpy="0 0 0" xyz="0 0 0"/>
      <geometry>
        <box size="0.005 0.0325 0.0325"/>
        <!-- <mesh filename="package://phantomx_description/meshes/connect.STL"  scale="1 1 1"/>-->
      </geometry>
    </collision>
  </link>
  <link name="femur_rf">
    <inertial>
      <origin rpy="0 0 0" xyz="1 0 0"/>
      <mass value="0.0286"/>
      <!-- <inertia ixx="0.000035572"  ixy="-0.000114256"  ixz="-0.000008584" iyy="0.000756486" iyz="-0.000001714" izz="0.000791714" /> -->
      <inertia ixx="0.00059" ixy="-0.0" ixz="-0.0" iyy="0.0" iyz="-0.0" izz="0.00059"/>
    </inertial>
    <visual>
      <origin rpy="0 1.57 0" xyz="0.075 0 0"/>
      <geometry>
        <!-- <box size="0.022 0.25 0.0325" /> -->
        <cylinder length="0.15" radius="0.015"/>
        <!--<mesh filename="package://phantomx_description/meshes/thigh_l.STL"  scale="1 1 1"/>-->
      </geometry>
      <material name="Grey">
        <color rgba="0.20 0.20 0.20 1.0"/>
      </material>
    </visual>
    <collision>
      <origin rpy="0 1.57 0" xyz="0.075 0 0"/>
      <geometry>
        <cylinder length="0.15" radius="0.015"/>
        <!-- <mesh filename="package://phantomx_description/meshes/thigh_l_coll.STL"  scale="1 1 1"/> -->
      </geometry>
    </collision>
  </link>
  <link name="tibia_rf">
    <inertial>
      <origin rpy="0 0 0" xyz="0 0 0"/>
      <mass value="0.0286"/>
      <!-- g/mm^2 -->
      <!-- <inertia ixx="35572"  ixy="-114256"  ixz="-8584" iyy="756486" iyz="-1714" izz="791714" /> -->
      <!-- <inertia ixx="0.000035572"  ixy="-0.000114256"  ixz="-0.000008584" iyy="0.000756486" iyz="-0.000001714" izz="0.000791714" /> -->
      <inertia ixx="0.00059" ixy="-0.0" ixz="-0.0" iyy="0.0" iyz="-0.0" izz="0.00059"/>
    </inertial>
    <visual>
      <origin rpy="1.57 0 1.57" xyz="0.125 0 0"/>
      <geometry>
        <cylinder length="0.25" radius="0.015"/>
        <!-- <box size="0.022 0.25 0.0325" /> -->
        <!--<mesh filename="package://phantomx_description/meshes/tibia_l.STL"  scale="1 1 1"/>-->
      </geometry>
      <material name="Orange">
        <color rgba="12 12 12 1.0"/>
      </material>
    </visual>
    <collision>
      <origin rpy="1.57 0 1.57" xyz="0.125 0 0"/>
      <geometry>
        <cylinder length="0.25" radius="0.015"/>
        <!-- <mesh filename="package://phantomx_description/meshes/tibia_l_coll.STL"  scale="1 1 1"/> -->
      </geometry>
    </collision>
  </link>
  <joint name="j_coxa_rf" type="revolute">
    <parent link="MP_BODY"/>
    <child link="coxa_rf"/>
    <origin rpy="0 0 5.576" xyz="0.175 -0.1  0.001116"/>
    <axis xyz="0 0 1"/>
    <limit effort="30" lower="-3.14" upper="3.14" velocity="0.5"/>
  </joint>
  <joint name="j_c2_rf" type="fixed">
    <parent link="coxa_rf"/>
    <child link="c2_rf"/>
    <origin rpy="0 0 0" xyz="0.0135 0 0"/>
    <limit effort="30" lower="-3.14" upper="3.14" velocity="0.5"/>
  </joint>
  <joint name="j_femur_rf" type="revolute">
    <parent link="c2_rf"/>
    <child link="femur_rf"/>
    <origin rpy=" 1.57 0 0" xyz="0 0 0"/>
    <axis xyz="0 0 1"/>
    <limit effort="30" lower="-3.14" upper="3.14" velocity="0.5"/>
  </joint>
  <joint name="j_tibia_rf" type="revolute">
    <parent link="femur_rf"/>
    <child link="tibia_rf"/>
    <origin rpy="0 0 0" xyz="0.125 0 0"/>
    <axis xyz="0 0 1"/>
    <limit effort="30" lower="-3.14" upper="3.14" velocity="0.5"/>
  </joint>
  <!-- <gazebo reference="$tibia_${suffix}">
        <mu1>1</mu1>
        <mu2>1</mu2>
        <fdir1>1 0 0</fdir1>
        <minDepth>0.005</minDepth>
        <maxContacts>1</maxContacts>
            <collision name="$tibia_${suffix}_collision">
                <geometry>
                    <sphere>
                    <radius>0.02175</radius>
                </sphere>
                </geometry>

            <surface>
                <friction>
                    <torsional>
                            <coefficient>10</coefficient>
                            <use_patch_radius>true</use_patch_radius>
                            <surface_radius>0.05</surface_radius>
                            <patch_radius>0.01</patch_radius>
                    </torsional>
            </friction>
            <contact>
                <poissons_ratio>0.5</poissons_ratio>
                <elastic_modulus>1e8</elastic_modulus>
            </contact>
        </surface>
    </collision>
    </gazebo> -->
  <!-- <joint name="j_coxa_${suffix}" type="revolute">
    <parent link="MP_BODY"/>
    <child link="coxa_${suffix}"/>
    <origin xyz="${xyz}" rpy="${rpy}" />
    <axis xyz="1 0 0" />
    <limit effort="2.8" velocity="5.6548668" lower="-2.6179939" upper="2.6179939" />
  </joint>

  <joint name="j_c2_${suffix}" type="fixed">
    <parent link="coxa_${suffix}"/>
    <child link="c2_${suffix}"/>
    <origin xyz="0 -0.033 0" rpy="0 1.5704 3.14159" />
  </joint>


  <joint name="j_femur_${suffix}" type="revolute">
    <parent link="c2_${suffix}"/>
    <child link="femur_${suffix}"/>
    <origin xyz="0 0.117 0" rpy=" -1.5707 0 3.14159" />
    <axis xyz="1 0 0" />
    <limit effort="2.8" velocity="5.6548668" lower="-2.6179939" upper="2.6179939" />
  </joint>

  <joint name="j_tibia_${suffix}" type="revolute">
    <parent link="femur_${suffix}"/>
    <child link="tibia_${suffix}"/>
    <origin xyz="0 ${femur_offset_y} ${femur_offset_z}" rpy="-1.5707 0 3.14159" />
    <axis xyz="1 0 0" />
    <limit effort="2.8" velocity="5.6548668" lower="-2.6179939" upper="2.6179939" />
  </joint> -->
  <transmission name="t_coxa_rf" type="ardent_model/SimpleTransmission">
    <joint name="j_coxa_rf"/>
    <actuator name="j_coxa_rf_motor"/>
    <mechanicalReduction>1</mechanicalReduction>
    <!-- <compensator k_belt="4000.0" mass_motor="0.05" kd_motor="15.0" lambda_motor="40.0" lambda_joint="40.0" lambda_combined="0.0"/> -->
  </transmission>
  <transmission name="t_femur_rf" type="ardent_model/SimpleTransmission">
    <joint name="j_femur_rf"/>
    <actuator name="j_femur_rf_motor"/>
    <mechanicalReduction>1</mechanicalReduction>
    <!-- <compensator k_belt="4000.0" mass_motor="0.05" kd_motor="15.0" lambda_motor="40.0" lambda_joint="40.0" lambda_combined="0.0"/> -->
  </transmission>
  <transmission name="t_tibia_rf" type="ardent_model/SimpleTransmission">
    <joint name="j_tibia_rf"/>
    <actuator name="j_tibia_rf_motor"/>
    <mechanicalReduction>1</mechanicalReduction>
    <!-- <compensator k_belt="4000.0" mass_motor="0.05" kd_motor="15.0" lambda_motor="40.0" lambda_joint="40.0" lambda_combined="0.0"/> -->
  </transmission>
  <!-- <transmission name="t_coxa_${suffix}">
    <type>transmission_interface/SimpleTransmission</type>
    <joint name="j_coxa_${suffix}">
      <hardwareInterface>hardware_interface/EffortJointInterface</hardwareInterface>    
    </joint>
    <actuator name="m_coxa_${suffix}">
      <hardwareInterface>hardware_interface/EffortJointInterface</hardwareInterface>
      <mechanicalReduction>1</mechanicalReduction>
    </actuator>
  </transmission>


   <transmission name="t_femur_${suffix}">
    <type>transmission_interface/SimpleTransmission</type>
    <joint name="j_femur_${suffix}">
      <hardwareInterface>hardware_interface/EffortJointInterface</hardwareInterface>    
    </joint>
    <actuator name="m_femur_${suffix}">
      <hardwareInterface>hardware_interface/EffortJointInterface</hardwareInterface>
      <mechanicalReduction>1</mechanicalReduction>
    </actuator>
  </transmission>


   <transmission name="t_tibia_${suffix}">
    <type>transmission_interface/SimpleTransmission</type>
    <joint name="j_tibia_${suffix}">
      <hardwareInterface>hardware_interface/EffortJointInterface</hardwareInterface>
    </joint>
    <actuator name="m_tibia_${suffix}">
      <hardwareInterface>hardware_interface/EffortJointInterface</hardwareInterface>
      <mechanicalReduction>1</mechanicalReduction>
    </actuator>
  </transmission> -->
  <gazebo reference="MP_BODY">
    <material>Gazebo/Orange</material>
  </gazebo>
  <gazebo reference="coxa_rf">
    <material>Gazebo/Black</material>
  </gazebo>
  <gazebo reference="c2_rf">
    <material>Gazebo/Orange</material>
  </gazebo>
  <gazebo reference="femur_rf">
    <material>Gazebo/Black</material>
  </gazebo>
  <gazebo reference="tibia_rf">
    <material>Gazebo/Orange</material>
  </gazebo>
  <link name="coxa_rm">
    <inertial>
      <origin rpy="0 0 0" xyz="0 0 0"/>
      <mass value="0.024357719"/>
      <inertia ixx="0.0051411124" ixy="-0.00057530255" ixz="-0.000024729049" iyy="0.0081915737" iyz="-0.000019223094" izz="0.0011379812"/>
    </inertial>
    <visual>
      <origin rpy="0 0 0" xyz="0 0 0"/>
      <geometry>
        <box size="0.022 0.045 0.0325"/>
        <!--<mesh filename="package://phantomx_description/meshes/connect.STL"  scale="1 1 1"/>-->
      </geometry>
      <material name="Grey">
        <color rgba="0.20 0.20 0.20 1.0"/>
      </material>
    </visual>
    <collision>
      <origin rpy="0 0 0" xyz="0 0 0"/>
      <geometry>
        <box size="0.022 0.045 0.0325"/>
        <!-- <mesh filename="package://phantomx_description/meshes/connect_coll.STL"  scale="1 1 1"/> -->
      </geometry>
    </collision>
  </link>
  <link name="c2_rm">
    <inertial>
      <origin rpy="0 0 0" xyz="0 0 0"/>
      <mass value="0.024357719"/>
      <inertia ixx="0.0051411124" ixy="-0.00057530255" ixz="-0.000024729049" iyy="0.0081915737" iyz="-0.000019223094" izz="0.0011379812"/>
    </inertial>
    <visual>
      <origin rpy="0 0 0" xyz="0 0 0"/>
      <geometry>
        <box size="0.005 0.0325 0.0325"/>
        <!-- <mesh filename="package://phantomx_description/meshes/connect.STL"  scale="1 1 1"/>-->
      </geometry>
      <material name="Orange">
        <color rgba="12 12 12 1.0"/>
      </material>
    </visual>
    <collision>
      <origin rpy="0 0 0" xyz="0 0 0"/>
      <geometry>
        <box size="0.005 0.0325 0.0325"/>
        <!-- <mesh filename="package://phantomx_description/meshes/connect.STL"  scale="1 1 1"/>-->
      </geometry>
    </collision>
  </link>
  <link name="femur_rm">
    <inertial>
      <origin rpy="0 0 0" xyz="1 0 0"/>
      <mass value="0.0286"/>
      <!-- <inertia ixx="0.000035572"  ixy="-0.000114256"  ixz="-0.000008584" iyy="0.000756486" iyz="-0.000001714" izz="0.000791714" /> -->
      <inertia ixx="0.00059" ixy="-0.0" ixz="-0.0" iyy="0.0" iyz="-0.0" izz="0.00059"/>
    </inertial>
    <visual>
      <origin rpy="0 1.57 0" xyz="0.075 0 0"/>
      <geometry>
        <!-- <box size="0.022 0.25 0.0325" /> -->
        <cylinder length="0.15" radius="0.015"/>
        <!--<mesh filename="package://phantomx_description/meshes/thigh_l.STL"  scale="1 1 1"/>-->
      </geometry>
      <material name="Grey">
        <color rgba="0.20 0.20 0.20 1.0"/>
      </material>
    </visual>
    <collision>
      <origin rpy="0 1.57 0" xyz="0.075 0 0"/>
      <geometry>
        <cylinder length="0.15" radius="0.015"/>
        <!-- <mesh filename="package://phantomx_description/meshes/thigh_l_coll.STL"  scale="1 1 1"/> -->
      </geometry>
    </collision>
  </link>
  <link name="tibia_rm">
    <inertial>
      <origin rpy="0 0 0" xyz="0 0 0"/>
      <mass value="0.0286"/>
      <!-- g/mm^2 -->
      <!-- <inertia ixx="35572"  ixy="-114256"  ixz="-8584" iyy="756486" iyz="-1714" izz="791714" /> -->
      <!-- <inertia ixx="0.000035572"  ixy="-0.000114256"  ixz="-0.000008584" iyy="0.000756486" iyz="-0.000001714" izz="0.000791714" /> -->
      <inertia ixx="0.00059" ixy="-0.0" ixz="-0.0" iyy="0.0" iyz="-0.0" izz="0.00059"/>
    </inertial>
    <visual>
      <origin rpy="1.57 0 1.57" xyz="0.125 0 0"/>
      <geometry>
        <cylinder length="0.25" radius="0.015"/>
        <!-- <box size="0.022 0.25 0.0325" /> -->
        <!--<mesh filename="package://phantomx_description/meshes/tibia_l.STL"  scale="1 1 1"/>-->
      </geometry>
      <material name="Orange">
        <color rgba="12 12 12 1.0"/>
      </material>
    </visual>
    <collision>
      <origin rpy="1.57 0 1.57" xyz="0.125 0 0"/>
      <geometry>
        <cylinder length="0.25" radius="0.015"/>
        <!-- <mesh filename="package://phantomx_description/meshes/tibia_l_coll.STL"  scale="1 1 1"/> -->
      </geometry>
    </collision>
  </link>
  <joint name="j_coxa_rm" type="revolute">
    <parent link="MP_BODY"/>
    <child link="coxa_rm"/>
    <origin rpy="0 0 -1.57" xyz="0 -0.2  0.001116"/>
    <axis xyz="0 0 1"/>
    <limit effort="30" lower="-3.14" upper="3.14" velocity="0.5"/>
  </joint>
  <joint name="j_c2_rm" type="fixed">
    <parent link="coxa_rm"/>
    <child link="c2_rm"/>
    <origin rpy="0 0 0" xyz="0.0135 0 0"/>
    <limit effort="30" lower="-3.14" upper="3.14" velocity="0.5"/>
  </joint>
  <joint name="j_femur_rm" type="revolute">
    <parent link="c2_rm"/>
    <child link="femur_rm"/>
    <origin rpy=" 1.57 0 0" xyz="0 0 0"/>
    <axis xyz="0 0 1"/>
    <limit effort="30" lower="-3.14" upper="3.14" velocity="0.5"/>
  </joint>
  <joint name="j_tibia_rm" type="revolute">
    <parent link="femur_rm"/>
    <child link="tibia_rm"/>
    <origin rpy="0 0 0" xyz="0.125 0 0"/>
    <axis xyz="0 0 1"/>
    <limit effort="30" lower="-3.14" upper="3.14" velocity="0.5"/>
  </joint>
  <!-- <gazebo reference="$tibia_${suffix}">
        <mu1>1</mu1>
        <mu2>1</mu2>
        <fdir1>1 0 0</fdir1>
        <minDepth>0.005</minDepth>
        <maxContacts>1</maxContacts>
            <collision name="$tibia_${suffix}_collision">
                <geometry>
                    <sphere>
                    <radius>0.02175</radius>
                </sphere>
                </geometry>

            <surface>
                <friction>
                    <torsional>
                            <coefficient>10</coefficient>
                            <use_patch_radius>true</use_patch_radius>
                            <surface_radius>0.05</surface_radius>
                            <patch_radius>0.01</patch_radius>
                    </torsional>
            </friction>
            <contact>
                <poissons_ratio>0.5</poissons_ratio>
                <elastic_modulus>1e8</elastic_modulus>
            </contact>
        </surface>
    </collision>
    </gazebo> -->
  <!-- <joint name="j_coxa_${suffix}" type="revolute">
    <parent link="MP_BODY"/>
    <child link="coxa_${suffix}"/>
    <origin xyz="${xyz}" rpy="${rpy}" />
    <axis xyz="1 0 0" />
    <limit effort="2.8" velocity="5.6548668" lower="-2.6179939" upper="2.6179939" />
  </joint>

  <joint name="j_c2_${suffix}" type="fixed">
    <parent link="coxa_${suffix}"/>
    <child link="c2_${suffix}"/>
    <origin xyz="0 -0.033 0" rpy="0 1.5704 3.14159" />
  </joint>


  <joint name="j_femur_${suffix}" type="revolute">
    <parent link="c2_${suffix}"/>
    <child link="femur_${suffix}"/>
    <origin xyz="0 0.117 0" rpy=" -1.5707 0 3.14159" />
    <axis xyz="1 0 0" />
    <limit effort="2.8" velocity="5.6548668" lower="-2.6179939" upper="2.6179939" />
  </joint>

  <joint name="j_tibia_${suffix}" type="revolute">
    <parent link="femur_${suffix}"/>
    <child link="tibia_${suffix}"/>
    <origin xyz="0 ${femur_offset_y} ${femur_offset_z}" rpy="-1.5707 0 3.14159" />
    <axis xyz="1 0 0" />
    <limit effort="2.8" velocity="5.6548668" lower="-2.6179939" upper="2.6179939" />
  </joint> -->
  <transmission name="t_coxa_rm" type="ardent_model/SimpleTransmission">
    <joint name="j_coxa_rm"/>
    <actuator name="j_coxa_rm_motor"/>
    <mechanicalReduction>1</mechanicalReduction>
    <!-- <compensator k_belt="4000.0" mass_motor="0.05" kd_motor="15.0" lambda_motor="40.0" lambda_joint="40.0" lambda_combined="0.0"/> -->
  </transmission>
  <transmission name="t_femur_rm" type="ardent_model/SimpleTransmission">
    <joint name="j_femur_rm"/>
    <actuator name="j_femur_rm_motor"/>
    <mechanicalReduction>1</mechanicalReduction>
    <!-- <compensator k_belt="4000.0" mass_motor="0.05" kd_motor="15.0" lambda_motor="40.0" lambda_joint="40.0" lambda_combined="0.0"/> -->
  </transmission>
  <transmission name="t_tibia_rm" type="ardent_model/SimpleTransmission">
    <joint name="j_tibia_rm"/>
    <actuator name="j_tibia_rm_motor"/>
    <mechanicalReduction>1</mechanicalReduction>
    <!-- <compensator k_belt="4000.0" mass_motor="0.05" kd_motor="15.0" lambda_motor="40.0" lambda_joint="40.0" lambda_combined="0.0"/> -->
  </transmission>
  <!-- <transmission name="t_coxa_${suffix}">
    <type>transmission_interface/SimpleTransmission</type>
    <joint name="j_coxa_${suffix}">
      <hardwareInterface>hardware_interface/EffortJointInterface</hardwareInterface>    
    </joint>
    <actuator name="m_coxa_${suffix}">
      <hardwareInterface>hardware_interface/EffortJointInterface</hardwareInterface>
      <mechanicalReduction>1</mechanicalReduction>
    </actuator>
  </transmission>


   <transmission name="t_femur_${suffix}">
    <type>transmission_interface/SimpleTransmission</type>
    <joint name="j_femur_${suffix}">
      <hardwareInterface>hardware_interface/EffortJointInterface</hardwareInterface>    
    </joint>
    <actuator name="m_femur_${suffix}">
      <hardwareInterface>hardware_interface/EffortJointInterface</hardwareInterface>
      <mechanicalReduction>1</mechanicalReduction>
    </actuator>
  </transmission>


   <transmission name="t_tibia_${suffix}">
    <type>transmission_interface/SimpleTransmission</type>
    <joint name="j_tibia_${suffix}">
      <hardwareInterface>hardware_interface/EffortJointInterface</hardwareInterface>
    </joint>
    <actuator name="m_tibia_${suffix}">
      <hardwareInterface>hardware_interface/EffortJointInterface</hardwareInterface>
      <mechanicalReduction>1</mechanicalReduction>
    </actuator>
  </transmission> -->
  <gazebo reference="MP_BODY">
    <material>Gazebo/Orange</material>
  </gazebo>
  <gazebo reference="coxa_rm">
    <material>Gazebo/Black</material>
  </gazebo>
  <gazebo reference="c2_rm">
    <material>Gazebo/Orange</material>
  </gazebo>
  <gazebo reference="femur_rm">
    <material>Gazebo/Black</material>
  </gazebo>
  <gazebo reference="tibia_rm">
    <material>Gazebo/Orange</material>
  </gazebo>
  <link name="coxa_rr">
    <inertial>
      <origin rpy="0 0 0" xyz="0 0 0"/>
      <mass value="0.024357719"/>
      <inertia ixx="0.0051411124" ixy="-0.00057530255" ixz="-0.000024729049" iyy="0.0081915737" iyz="-0.000019223094" izz="0.0011379812"/>
    </inertial>
    <visual>
      <origin rpy="0 0 0" xyz="0 0 0"/>
      <geometry>
        <box size="0.022 0.045 0.0325"/>
        <!--<mesh filename="package://phantomx_description/meshes/connect.STL"  scale="1 1 1"/>-->
      </geometry>
      <material name="Grey">
        <color rgba="0.20 0.20 0.20 1.0"/>
      </material>
    </visual>
    <collision>
      <origin rpy="0 0 0" xyz="0 0 0"/>
      <geometry>
        <box size="0.022 0.045 0.0325"/>
        <!-- <mesh filename="package://phantomx_description/meshes/connect_coll.STL"  scale="1 1 1"/> -->
      </geometry>
    </collision>
  </link>
  <link name="c2_rr">
    <inertial>
      <origin rpy="0 0 0" xyz="0 0 0"/>
      <mass value="0.024357719"/>
      <inertia ixx="0.0051411124" ixy="-0.00057530255" ixz="-0.000024729049" iyy="0.0081915737" iyz="-0.000019223094" izz="0.0011379812"/>
    </inertial>
    <visual>
      <origin rpy="0 0 0" xyz="0 0 0"/>
      <geometry>
        <box size="0.005 0.0325 0.0325"/>
        <!-- <mesh filename="package://phantomx_description/meshes/connect.STL"  scale="1 1 1"/>-->
      </geometry>
      <material name="Orange">
        <color rgba="12 12 12 1.0"/>
      </material>
    </visual>
    <collision>
      <origin rpy="0 0 0" xyz="0 0 0"/>
      <geometry>
        <box size="0.005 0.0325 0.0325"/>
        <!-- <mesh filename="package://phantomx_description/meshes/connect.STL"  scale="1 1 1"/>-->
      </geometry>
    </collision>
  </link>
  <link name="femur_rr">
    <inertial>
      <origin rpy="0 0 0" xyz="1 0 0"/>
      <mass value="0.0286"/>
      <!-- <inertia ixx="0.000035572"  ixy="-0.000114256"  ixz="-0.000008584" iyy="0.000756486" iyz="-0.000001714" izz="0.000791714" /> -->
      <inertia ixx="0.00059" ixy="-0.0" ixz="-0.0" iyy="0.0" iyz="-0.0" izz="0.00059"/>
    </inertial>
    <visual>
      <origin rpy="0 1.57 0" xyz="0.075 0 0"/>
      <geometry>
        <!-- <box size="0.022 0.25 0.0325" /> -->
        <cylinder length="0.15" radius="0.015"/>
        <!--<mesh filename="package://phantomx_description/meshes/thigh_l.STL"  scale="1 1 1"/>-->
      </geometry>
      <material name="Grey">
        <color rgba="0.20 0.20 0.20 1.0"/>
      </material>
    </visual>
    <collision>
      <origin rpy="0 1.57 0" xyz="0.075 0 0"/>
      <geometry>
        <cylinder length="0.15" radius="0.015"/>
        <!-- <mesh filename="package://phantomx_description/meshes/thigh_l_coll.STL"  scale="1 1 1"/> -->
      </geometry>
    </collision>
  </link>
  <link name="tibia_rr">
    <inertial>
      <origin rpy="0 0 0" xyz="0 0 0"/>
      <mass value="0.0286"/>
      <!-- g/mm^2 -->
      <!-- <inertia ixx="35572"  ixy="-114256"  ixz="-8584" iyy="756486" iyz="-1714" izz="791714" /> -->
      <!-- <inertia ixx="0.000035572"  ixy="-0.000114256"  ixz="-0.000008584" iyy="0.000756486" iyz="-0.000001714" izz="0.000791714" /> -->
      <inertia ixx="0.00059" ixy="-0.0" ixz="-0.0" iyy="0.0" iyz="-0.0" izz="0.00059"/>
    </inertial>
    <visual>
      <origin rpy="1.57 0 1.57" xyz="0.125 0 0"/>
      <geometry>
        <cylinder length="0.25" radius="0.015"/>
        <!-- <box size="0.022 0.25 0.0325" /> -->
        <!--<mesh filename="package://phantomx_description/meshes/tibia_l.STL"  scale="1 1 1"/>-->
      </geometry>
      <material name="Orange">
        <color rgba="12 12 12 1.0"/>
      </material>
    </visual>
    <collision>
      <origin rpy="1.57 0 1.57" xyz="0.125 0 0"/>
      <geometry>
        <cylinder length="0.25" radius="0.015"/>
        <!-- <mesh filename="package://phantomx_description/meshes/tibia_l_coll.STL"  scale="1 1 1"/> -->
      </geometry>
    </collision>
  </link>
  <joint name="j_coxa_rr" type="revolute">
    <parent link="MP_BODY"/>
    <child link="coxa_rr"/>
    <origin rpy="0 0 -2.62" xyz="-0.175 -0.1  0.001116"/>
    <axis xyz="0 0 1"/>
    <limit effort="30" lower="-3.14" upper="3.14" velocity="0.5"/>
  </joint>
  <joint name="j_c2_rr" type="fixed">
    <parent link="coxa_rr"/>
    <child link="c2_rr"/>
    <origin rpy="0 0 0" xyz="0.0135 0 0"/>
    <limit effort="30" lower="-3.14" upper="3.14" velocity="0.5"/>
  </joint>
  <joint name="j_femur_rr" type="revolute">
    <parent link="c2_rr"/>
    <child link="femur_rr"/>
    <origin rpy=" 1.57 0 0" xyz="0 0 0"/>
    <axis xyz="0 0 1"/>
    <limit effort="30" lower="-3.14" upper="3.14" velocity="0.5"/>
  </joint>
  <joint name="j_tibia_rr" type="revolute">
    <parent link="femur_rr"/>
    <child link="tibia_rr"/>
    <origin rpy="0 0 0" xyz="0.125 0 0"/>
    <axis xyz="0 0 1"/>
    <limit effort="30" lower="-3.14" upper="3.14" velocity="0.5"/>
  </joint>
  <!-- <gazebo reference="$tibia_${suffix}">
        <mu1>1</mu1>
        <mu2>1</mu2>
        <fdir1>1 0 0</fdir1>
        <minDepth>0.005</minDepth>
        <maxContacts>1</maxContacts>
            <collision name="$tibia_${suffix}_collision">
                <geometry>
                    <sphere>
                    <radius>0.02175</radius>
                </sphere>
                </geometry>

            <surface>
                <friction>
                    <torsional>
                            <coefficient>10</coefficient>
                            <use_patch_radius>true</use_patch_radius>
                            <surface_radius>0.05</surface_radius>
                            <patch_radius>0.01</patch_radius>
                    </torsional>
            </friction>
            <contact>
                <poissons_ratio>0.5</poissons_ratio>
                <elastic_modulus>1e8</elastic_modulus>
            </contact>
        </surface>
    </collision>
    </gazebo> -->
  <!-- <joint name="j_coxa_${suffix}" type="revolute">
    <parent link="MP_BODY"/>
    <child link="coxa_${suffix}"/>
    <origin xyz="${xyz}" rpy="${rpy}" />
    <axis xyz="1 0 0" />
    <limit effort="2.8" velocity="5.6548668" lower="-2.6179939" upper="2.6179939" />
  </joint>

  <joint name="j_c2_${suffix}" type="fixed">
    <parent link="coxa_${suffix}"/>
    <child link="c2_${suffix}"/>
    <origin xyz="0 -0.033 0" rpy="0 1.5704 3.14159" />
  </joint>


  <joint name="j_femur_${suffix}" type="revolute">
    <parent link="c2_${suffix}"/>
    <child link="femur_${suffix}"/>
    <origin xyz="0 0.117 0" rpy=" -1.5707 0 3.14159" />
    <axis xyz="1 0 0" />
    <limit effort="2.8" velocity="5.6548668" lower="-2.6179939" upper="2.6179939" />
  </joint>

  <joint name="j_tibia_${suffix}" type="revolute">
    <parent link="femur_${suffix}"/>
    <child link="tibia_${suffix}"/>
    <origin xyz="0 ${femur_offset_y} ${femur_offset_z}" rpy="-1.5707 0 3.14159" />
    <axis xyz="1 0 0" />
    <limit effort="2.8" velocity="5.6548668" lower="-2.6179939" upper="2.6179939" />
  </joint> -->
  <transmission name="t_coxa_rr" type="ardent_model/SimpleTransmission">
    <joint name="j_coxa_rr"/>
    <actuator name="j_coxa_rr_motor"/>
    <mechanicalReduction>1</mechanicalReduction>
    <!-- <compensator k_belt="4000.0" mass_motor="0.05" kd_motor="15.0" lambda_motor="40.0" lambda_joint="40.0" lambda_combined="0.0"/> -->
  </transmission>
  <transmission name="t_femur_rr" type="ardent_model/SimpleTransmission">
    <joint name="j_femur_rr"/>
    <actuator name="j_femur_rr_motor"/>
    <mechanicalReduction>1</mechanicalReduction>
    <!-- <compensator k_belt="4000.0" mass_motor="0.05" kd_motor="15.0" lambda_motor="40.0" lambda_joint="40.0" lambda_combined="0.0"/> -->
  </transmission>
  <transmission name="t_tibia_rr" type="ardent_model/SimpleTransmission">
    <joint name="j_tibia_rr"/>
    <actuator name="j_tibia_rr_motor"/>
    <mechanicalReduction>1</mechanicalReduction>
    <!-- <compensator k_belt="4000.0" mass_motor="0.05" kd_motor="15.0" lambda_motor="40.0" lambda_joint="40.0" lambda_combined="0.0"/> -->
  </transmission>
  <!-- <transmission name="t_coxa_${suffix}">
    <type>transmission_interface/SimpleTransmission</type>
    <joint name="j_coxa_${suffix}">
      <hardwareInterface>hardware_interface/EffortJointInterface</hardwareInterface>    
    </joint>
    <actuator name="m_coxa_${suffix}">
      <hardwareInterface>hardware_interface/EffortJointInterface</hardwareInterface>
      <mechanicalReduction>1</mechanicalReduction>
    </actuator>
  </transmission>


   <transmission name="t_femur_${suffix}">
    <type>transmission_interface/SimpleTransmission</type>
    <joint name="j_femur_${suffix}">
      <hardwareInterface>hardware_interface/EffortJointInterface</hardwareInterface>    
    </joint>
    <actuator name="m_femur_${suffix}">
      <hardwareInterface>hardware_interface/EffortJointInterface</hardwareInterface>
      <mechanicalReduction>1</mechanicalReduction>
    </actuator>
  </transmission>


   <transmission name="t_tibia_${suffix}">
    <type>transmission_interface/SimpleTransmission</type>
    <joint name="j_tibia_${suffix}">
      <hardwareInterface>hardware_interface/EffortJointInterface</hardwareInterface>
    </joint>
    <actuator name="m_tibia_${suffix}">
      <hardwareInterface>hardware_interface/EffortJointInterface</hardwareInterface>
      <mechanicalReduction>1</mechanicalReduction>
    </actuator>
  </transmission> -->
  <gazebo reference="MP_BODY">
    <material>Gazebo/Orange</material>
  </gazebo>
  <gazebo reference="coxa_rr">
    <material>Gazebo/Black</material>
  </gazebo>
  <gazebo reference="c2_rr">
    <material>Gazebo/Orange</material>
  </gazebo>
  <gazebo reference="femur_rr">
    <material>Gazebo/Black</material>
  </gazebo>
  <gazebo reference="tibia_rr">
    <material>Gazebo/Orange</material>
  </gazebo>
  <link name="coxa_lf">
    <inertial>
      <origin rpy="0 0 0" xyz="0 0 0"/>
      <mass value="0.024357719"/>
      <inertia ixx="0.0051411124" ixy="-0.00057530255" ixz="-0.000024729049" iyy="0.0081915737" iyz="-0.000019223094" izz="0.0011379812"/>
    </inertial>
    <visual>
      <origin rpy="0 0 0" xyz="0 0 0"/>
      <geometry>
        <box size="0.022 0.045 0.0325"/>
        <!--<mesh filename="package://phantomx_description/meshes/connect.STL"  scale="1 1 1"/>-->
      </geometry>
      <material name="Grey">
        <color rgba="0.20 0.20 0.20 1.0"/>
      </material>
    </visual>
    <collision>
      <origin rpy="0 0 0" xyz="0 0 0"/>
      <geometry>
        <box size="0.022 0.045 0.0325"/>
        <!-- <mesh filename="package://phantomx_description/meshes/connect_coll.STL"  scale="1 1 1"/> -->
      </geometry>
    </collision>
  </link>
  <link name="c2_lf">
    <inertial>
      <origin rpy="0 0 0" xyz="0 0 0"/>
      <mass value="0.024357719"/>
      <inertia ixx="0.0051411124" ixy="-0.00057530255" ixz="-0.000024729049" iyy="0.0081915737" iyz="-0.000019223094" izz="0.0011379812"/>
    </inertial>
    <visual>
      <origin rpy="0 0 0" xyz="0 0 0"/>
      <geometry>
        <box size="0.005 0.0325 0.0325"/>
        <!-- <mesh filename="package://phantomx_description/meshes/connect.STL"  scale="1 1 1"/>-->
      </geometry>
      <material name="Orange">
        <color rgba="12 12 12 1.0"/>
      </material>
    </visual>
    <collision>
      <origin rpy="0 0 0" xyz="0 0 0"/>
      <geometry>
        <box size="0.005 0.0325 0.0325"/>
        <!-- <mesh filename="package://phantomx_description/meshes/connect.STL"  scale="1 1 1"/>-->
      </geometry>
    </collision>
  </link>
  <link name="femur_lf">
    <inertial>
      <origin rpy="0 0 0" xyz="1 0 0"/>
      <mass value="0.0286"/>
      <!-- <inertia ixx="0.000035572"  ixy="-0.000114256"  ixz="-0.000008584" iyy="0.000756486" iyz="-0.000001714" izz="0.000791714" /> -->
      <inertia ixx="0.00059" ixy="-0.0" ixz="-0.0" iyy="0.0" iyz="-0.0" izz="0.00059"/>
    </inertial>
    <visual>
      <origin rpy="0 1.57 0" xyz="0.075 0 0"/>
      <geometry>
        <!-- <box size="0.022 0.25 0.0325" /> -->
        <cylinder length="0.15" radius="0.015"/>
        <!--<mesh filename="package://phantomx_description/meshes/thigh_l.STL"  scale="1 1 1"/>-->
      </geometry>
      <material name="Grey">
        <color rgba="0.20 0.20 0.20 1.0"/>
      </material>
    </visual>
    <collision>
      <origin rpy="0 1.57 0" xyz="0.075 0 0"/>
      <geometry>
        <cylinder length="0.15" radius="0.015"/>
        <!-- <mesh filename="package://phantomx_description/meshes/thigh_l_coll.STL"  scale="1 1 1"/> -->
      </geometry>
    </collision>
  </link>
  <link name="tibia_lf">
    <inertial>
      <origin rpy="0 0 0" xyz="0 0 0"/>
      <mass value="0.0286"/>
      <!-- g/mm^2 -->
      <!-- <inertia ixx="35572"  ixy="-114256"  ixz="-8584" iyy="756486" iyz="-1714" izz="791714" /> -->
      <!-- <inertia ixx="0.000035572"  ixy="-0.000114256"  ixz="-0.000008584" iyy="0.000756486" iyz="-0.000001714" izz="0.000791714" /> -->
      <inertia ixx="0.00059" ixy="-0.0" ixz="-0.0" iyy="0.0" iyz="-0.0" izz="0.00059"/>
    </inertial>
    <visual>
      <origin rpy="1.57 0 1.57" xyz="0.125 0 0"/>
      <geometry>
        <cylinder length="0.25" radius="0.015"/>
        <!-- <box size="0.022 0.25 0.0325" /> -->
        <!--<mesh filename="package://phantomx_description/meshes/tibia_l.STL"  scale="1 1 1"/>-->
      </geometry>
      <material name="Orange">
        <color rgba="12 12 12 1.0"/>
      </material>
    </visual>
    <collision>
      <origin rpy="1.57 0 1.57" xyz="0.125 0 0"/>
      <geometry>
        <cylinder length="0.25" radius="0.015"/>
        <!-- <mesh filename="package://phantomx_description/meshes/tibia_l_coll.STL"  scale="1 1 1"/> -->
      </geometry>
    </collision>
  </link>
  <joint name="j_coxa_lf" type="revolute">
    <parent link="MP_BODY"/>
    <child link="coxa_lf"/>
    <origin rpy="0 0 0.52" xyz="0.175 0.1  0.001116"/>
    <axis xyz="0 0 1"/>
    <limit effort="30" lower="-3.14" upper="3.14" velocity="0.5"/>
  </joint>
  <joint name="j_c2_lf" type="fixed">
    <parent link="coxa_lf"/>
    <child link="c2_lf"/>
    <origin rpy="0 0 0" xyz="0.0135 0 0"/>
    <limit effort="30" lower="-3.14" upper="3.14" velocity="0.5"/>
  </joint>
  <joint name="j_femur_lf" type="revolute">
    <parent link="c2_lf"/>
    <child link="femur_lf"/>
    <origin rpy=" 1.57 0 0" xyz="0 0 0"/>
    <axis xyz="0 0 1"/>
    <limit effort="30" lower="-3.14" upper="3.14" velocity="0.5"/>
  </joint>
  <joint name="j_tibia_lf" type="revolute">
    <parent link="femur_lf"/>
    <child link="tibia_lf"/>
    <origin rpy="0 0 0" xyz="0.125 0 0"/>
    <axis xyz="0 0 1"/>
    <limit effort="30" lower="-3.14" upper="3.14" velocity="0.5"/>
  </joint>
  <!-- <gazebo reference="$tibia_${suffix}">
        <mu1>1</mu1>
        <mu2>1</mu2>
        <fdir1>1 0 0</fdir1>
        <minDepth>0.005</minDepth>
        <maxContacts>1</maxContacts>
            <collision name="$tibia_${suffix}_collision">
                <geometry>
                    <sphere>
                    <radius>0.02175</radius>
                </sphere>
                </geometry>

            <surface>
                <friction>
                    <torsional>
                            <coefficient>10</coefficient>
                            <use_patch_radius>true</use_patch_radius>
                            <surface_radius>0.05</surface_radius>
                            <patch_radius>0.01</patch_radius>
                    </torsional>
            </friction>
            <contact>
                <poissons_ratio>0.5</poissons_ratio>
                <elastic_modulus>1e8</elastic_modulus>
            </contact>
        </surface>
    </collision>
    </gazebo> -->
  <!-- <joint name="j_coxa_${suffix}" type="revolute">
    <parent link="MP_BODY"/>
    <child link="coxa_${suffix}"/>
    <origin xyz="${xyz}" rpy="${rpy}" />
    <axis xyz="1 0 0" />
    <limit effort="2.8" velocity="5.6548668" lower="-2.6179939" upper="2.6179939" />
  </joint>

  <joint name="j_c2_${suffix}" type="fixed">
    <parent link="coxa_${suffix}"/>
    <child link="c2_${suffix}"/>
    <origin xyz="0 -0.033 0" rpy="0 1.5704 3.14159" />
  </joint>


  <joint name="j_femur_${suffix}" type="revolute">
    <parent link="c2_${suffix}"/>
    <child link="femur_${suffix}"/>
    <origin xyz="0 0.117 0" rpy=" -1.5707 0 3.14159" />
    <axis xyz="1 0 0" />
    <limit effort="2.8" velocity="5.6548668" lower="-2.6179939" upper="2.6179939" />
  </joint>

  <joint name="j_tibia_${suffix}" type="revolute">
    <parent link="femur_${suffix}"/>
    <child link="tibia_${suffix}"/>
    <origin xyz="0 ${femur_offset_y} ${femur_offset_z}" rpy="-1.5707 0 3.14159" />
    <axis xyz="1 0 0" />
    <limit effort="2.8" velocity="5.6548668" lower="-2.6179939" upper="2.6179939" />
  </joint> -->
  <transmission name="t_coxa_lf" type="ardent_model/SimpleTransmission">
    <joint name="j_coxa_lf"/>
    <actuator name="j_coxa_lf_motor"/>
    <mechanicalReduction>1</mechanicalReduction>
    <!-- <compensator k_belt="4000.0" mass_motor="0.05" kd_motor="15.0" lambda_motor="40.0" lambda_joint="40.0" lambda_combined="0.0"/> -->
  </transmission>
  <transmission name="t_femur_lf" type="ardent_model/SimpleTransmission">
    <joint name="j_femur_lf"/>
    <actuator name="j_femur_lf_motor"/>
    <mechanicalReduction>1</mechanicalReduction>
    <!-- <compensator k_belt="4000.0" mass_motor="0.05" kd_motor="15.0" lambda_motor="40.0" lambda_joint="40.0" lambda_combined="0.0"/> -->
  </transmission>
  <transmission name="t_tibia_lf" type="ardent_model/SimpleTransmission">
    <joint name="j_tibia_lf"/>
    <actuator name="j_tibia_lf_motor"/>
    <mechanicalReduction>1</mechanicalReduction>
    <!-- <compensator k_belt="4000.0" mass_motor="0.05" kd_motor="15.0" lambda_motor="40.0" lambda_joint="40.0" lambda_combined="0.0"/> -->
  </transmission>
  <!-- <transmission name="t_coxa_${suffix}">
    <type>transmission_interface/SimpleTransmission</type>
    <joint name="j_coxa_${suffix}">
      <hardwareInterface>hardware_interface/EffortJointInterface</hardwareInterface>    
    </joint>
    <actuator name="m_coxa_${suffix}">
      <hardwareInterface>hardware_interface/EffortJointInterface</hardwareInterface>
      <mechanicalReduction>1</mechanicalReduction>
    </actuator>
  </transmission>


   <transmission name="t_femur_${suffix}">
    <type>transmission_interface/SimpleTransmission</type>
    <joint name="j_femur_${suffix}">
      <hardwareInterface>hardware_interface/EffortJointInterface</hardwareInterface>    
    </joint>
    <actuator name="m_femur_${suffix}">
      <hardwareInterface>hardware_interface/EffortJointInterface</hardwareInterface>
      <mechanicalReduction>1</mechanicalReduction>
    </actuator>
  </transmission>


   <transmission name="t_tibia_${suffix}">
    <type>transmission_interface/SimpleTransmission</type>
    <joint name="j_tibia_${suffix}">
      <hardwareInterface>hardware_interface/EffortJointInterface</hardwareInterface>
    </joint>
    <actuator name="m_tibia_${suffix}">
      <hardwareInterface>hardware_interface/EffortJointInterface</hardwareInterface>
      <mechanicalReduction>1</mechanicalReduction>
    </actuator>
  </transmission> -->
  <gazebo reference="MP_BODY">
    <material>Gazebo/Orange</material>
  </gazebo>
  <gazebo reference="coxa_lf">
    <material>Gazebo/Black</material>
  </gazebo>
  <gazebo reference="c2_lf">
    <material>Gazebo/Orange</material>
  </gazebo>
  <gazebo reference="femur_lf">
    <material>Gazebo/Black</material>
  </gazebo>
  <gazebo reference="tibia_lf">
    <material>Gazebo/Orange</material>
  </gazebo>
  <link name="coxa_lm">
    <inertial>
      <origin rpy="0 0 0" xyz="0 0 0"/>
      <mass value="0.024357719"/>
      <inertia ixx="0.0051411124" ixy="-0.00057530255" ixz="-0.000024729049" iyy="0.0081915737" iyz="-0.000019223094" izz="0.0011379812"/>
    </inertial>
    <visual>
      <origin rpy="0 0 0" xyz="0 0 0"/>
      <geometry>
        <box size="0.022 0.045 0.0325"/>
        <!--<mesh filename="package://phantomx_description/meshes/connect.STL"  scale="1 1 1"/>-->
      </geometry>
      <material name="Grey">
        <color rgba="0.20 0.20 0.20 1.0"/>
      </material>
    </visual>
    <collision>
      <origin rpy="0 0 0" xyz="0 0 0"/>
      <geometry>
        <box size="0.022 0.045 0.0325"/>
        <!-- <mesh filename="package://phantomx_description/meshes/connect_coll.STL"  scale="1 1 1"/> -->
      </geometry>
    </collision>
  </link>
  <link name="c2_lm">
    <inertial>
      <origin rpy="0 0 0" xyz="0 0 0"/>
      <mass value="0.024357719"/>
      <inertia ixx="0.0051411124" ixy="-0.00057530255" ixz="-0.000024729049" iyy="0.0081915737" iyz="-0.000019223094" izz="0.0011379812"/>
    </inertial>
    <visual>
      <origin rpy="0 0 0" xyz="0 0 0"/>
      <geometry>
        <box size="0.005 0.0325 0.0325"/>
        <!-- <mesh filename="package://phantomx_description/meshes/connect.STL"  scale="1 1 1"/>-->
      </geometry>
      <material name="Orange">
        <color rgba="12 12 12 1.0"/>
      </material>
    </visual>
    <collision>
      <origin rpy="0 0 0" xyz="0 0 0"/>
      <geometry>
        <box size="0.005 0.0325 0.0325"/>
        <!-- <mesh filename="package://phantomx_description/meshes/connect.STL"  scale="1 1 1"/>-->
      </geometry>
    </collision>
  </link>
  <link name="femur_lm">
    <inertial>
      <origin rpy="0 0 0" xyz="1 0 0"/>
      <mass value="0.0286"/>
      <!-- <inertia ixx="0.000035572"  ixy="-0.000114256"  ixz="-0.000008584" iyy="0.000756486" iyz="-0.000001714" izz="0.000791714" /> -->
      <inertia ixx="0.00059" ixy="-0.0" ixz="-0.0" iyy="0.0" iyz="-0.0" izz="0.00059"/>
    </inertial>
    <visual>
      <origin rpy="0 1.57 0" xyz="0.075 0 0"/>
      <geometry>
        <!-- <box size="0.022 0.25 0.0325" /> -->
        <cylinder length="0.15" radius="0.015"/>
        <!--<mesh filename="package://phantomx_description/meshes/thigh_l.STL"  scale="1 1 1"/>-->
      </geometry>
      <material name="Grey">
        <color rgba="0.20 0.20 0.20 1.0"/>
      </material>
    </visual>
    <collision>
      <origin rpy="0 1.57 0" xyz="0.075 0 0"/>
      <geometry>
        <cylinder length="0.15" radius="0.015"/>
        <!-- <mesh filename="package://phantomx_description/meshes/thigh_l_coll.STL"  scale="1 1 1"/> -->
      </geometry>
    </collision>
  </link>
  <link name="tibia_lm">
    <inertial>
      <origin rpy="0 0 0" xyz="0 0 0"/>
      <mass value="0.0286"/>
      <!-- g/mm^2 -->
      <!-- <inertia ixx="35572"  ixy="-114256"  ixz="-8584" iyy="756486" iyz="-1714" izz="791714" /> -->
      <!-- <inertia ixx="0.000035572"  ixy="-0.000114256"  ixz="-0.000008584" iyy="0.000756486" iyz="-0.000001714" izz="0.000791714" /> -->
      <inertia ixx="0.00059" ixy="-0.0" ixz="-0.0" iyy="0.0" iyz="-0.0" izz="0.00059"/>
    </inertial>
    <visual>
      <origin rpy="1.57 0 1.57" xyz="0.125 0 0"/>
      <geometry>
        <cylinder length="0.25" radius="0.015"/>
        <!-- <box size="0.022 0.25 0.0325" /> -->
        <!--<mesh filename="package://phantomx_description/meshes/tibia_l.STL"  scale="1 1 1"/>-->
      </geometry>
      <material name="Orange">
        <color rgba="12 12 12 1.0"/>
      </material>
    </visual>
    <collision>
      <origin rpy="1.57 0 1.57" xyz="0.125 0 0"/>
      <geometry>
        <cylinder length="0.25" radius="0.015"/>
        <!-- <mesh filename="package://phantomx_description/meshes/tibia_l_coll.STL"  scale="1 1 1"/> -->
      </geometry>
    </collision>
  </link>
  <joint name="j_coxa_lm" type="revolute">
    <parent link="MP_BODY"/>
    <child link="coxa_lm"/>
    <origin rpy="0 0 1.57" xyz="0 0.2  0.001116"/>
    <axis xyz="0 0 1"/>
    <limit effort="30" lower="-3.14" upper="3.14" velocity="0.5"/>
  </joint>
  <joint name="j_c2_lm" type="fixed">
    <parent link="coxa_lm"/>
    <child link="c2_lm"/>
    <origin rpy="0 0 0" xyz="0.0135 0 0"/>
    <limit effort="30" lower="-3.14" upper="3.14" velocity="0.5"/>
  </joint>
  <joint name="j_femur_lm" type="revolute">
    <parent link="c2_lm"/>
    <child link="femur_lm"/>
    <origin rpy=" 1.57 0 0" xyz="0 0 0"/>
    <axis xyz="0 0 1"/>
    <limit effort="30" lower="-3.14" upper="3.14" velocity="0.5"/>
  </joint>
  <joint name="j_tibia_lm" type="revolute">
    <parent link="femur_lm"/>
    <child link="tibia_lm"/>
    <origin rpy="0 0 0" xyz="0.125 0 0"/>
    <axis xyz="0 0 1"/>
    <limit effort="30" lower="-3.14" upper="3.14" velocity="0.5"/>
  </joint>
  <!-- <gazebo reference="$tibia_${suffix}">
        <mu1>1</mu1>
        <mu2>1</mu2>
        <fdir1>1 0 0</fdir1>
        <minDepth>0.005</minDepth>
        <maxContacts>1</maxContacts>
            <collision name="$tibia_${suffix}_collision">
                <geometry>
                    <sphere>
                    <radius>0.02175</radius>
                </sphere>
                </geometry>

            <surface>
                <friction>
                    <torsional>
                            <coefficient>10</coefficient>
                            <use_patch_radius>true</use_patch_radius>
                            <surface_radius>0.05</surface_radius>
                            <patch_radius>0.01</patch_radius>
                    </torsional>
            </friction>
            <contact>
                <poissons_ratio>0.5</poissons_ratio>
                <elastic_modulus>1e8</elastic_modulus>
            </contact>
        </surface>
    </collision>
    </gazebo> -->
  <!-- <joint name="j_coxa_${suffix}" type="revolute">
    <parent link="MP_BODY"/>
    <child link="coxa_${suffix}"/>
    <origin xyz="${xyz}" rpy="${rpy}" />
    <axis xyz="1 0 0" />
    <limit effort="2.8" velocity="5.6548668" lower="-2.6179939" upper="2.6179939" />
  </joint>

  <joint name="j_c2_${suffix}" type="fixed">
    <parent link="coxa_${suffix}"/>
    <child link="c2_${suffix}"/>
    <origin xyz="0 -0.033 0" rpy="0 1.5704 3.14159" />
  </joint>


  <joint name="j_femur_${suffix}" type="revolute">
    <parent link="c2_${suffix}"/>
    <child link="femur_${suffix}"/>
    <origin xyz="0 0.117 0" rpy=" -1.5707 0 3.14159" />
    <axis xyz="1 0 0" />
    <limit effort="2.8" velocity="5.6548668" lower="-2.6179939" upper="2.6179939" />
  </joint>

  <joint name="j_tibia_${suffix}" type="revolute">
    <parent link="femur_${suffix}"/>
    <child link="tibia_${suffix}"/>
    <origin xyz="0 ${femur_offset_y} ${femur_offset_z}" rpy="-1.5707 0 3.14159" />
    <axis xyz="1 0 0" />
    <limit effort="2.8" velocity="5.6548668" lower="-2.6179939" upper="2.6179939" />
  </joint> -->
  <transmission name="t_coxa_lm" type="ardent_model/SimpleTransmission">
    <joint name="j_coxa_lm"/>
    <actuator name="j_coxa_lm_motor"/>
    <mechanicalReduction>1</mechanicalReduction>
    <!-- <compensator k_belt="4000.0" mass_motor="0.05" kd_motor="15.0" lambda_motor="40.0" lambda_joint="40.0" lambda_combined="0.0"/> -->
  </transmission>
  <transmission name="t_femur_lm" type="ardent_model/SimpleTransmission">
    <joint name="j_femur_lm"/>
    <actuator name="j_femur_lm_motor"/>
    <mechanicalReduction>1</mechanicalReduction>
    <!-- <compensator k_belt="4000.0" mass_motor="0.05" kd_motor="15.0" lambda_motor="40.0" lambda_joint="40.0" lambda_combined="0.0"/> -->
  </transmission>
  <transmission name="t_tibia_lm" type="ardent_model/SimpleTransmission">
    <joint name="j_tibia_lm"/>
    <actuator name="j_tibia_lm_motor"/>
    <mechanicalReduction>1</mechanicalReduction>
    <!-- <compensator k_belt="4000.0" mass_motor="0.05" kd_motor="15.0" lambda_motor="40.0" lambda_joint="40.0" lambda_combined="0.0"/> -->
  </transmission>
  <!-- <transmission name="t_coxa_${suffix}">
    <type>transmission_interface/SimpleTransmission</type>
    <joint name="j_coxa_${suffix}">
      <hardwareInterface>hardware_interface/EffortJointInterface</hardwareInterface>    
    </joint>
    <actuator name="m_coxa_${suffix}">
      <hardwareInterface>hardware_interface/EffortJointInterface</hardwareInterface>
      <mechanicalReduction>1</mechanicalReduction>
    </actuator>
  </transmission>


   <transmission name="t_femur_${suffix}">
    <type>transmission_interface/SimpleTransmission</type>
    <joint name="j_femur_${suffix}">
      <hardwareInterface>hardware_interface/EffortJointInterface</hardwareInterface>    
    </joint>
    <actuator name="m_femur_${suffix}">
      <hardwareInterface>hardware_interface/EffortJointInterface</hardwareInterface>
      <mechanicalReduction>1</mechanicalReduction>
    </actuator>
  </transmission>


   <transmission name="t_tibia_${suffix}">
    <type>transmission_interface/SimpleTransmission</type>
    <joint name="j_tibia_${suffix}">
      <hardwareInterface>hardware_interface/EffortJointInterface</hardwareInterface>
    </joint>
    <actuator name="m_tibia_${suffix}">
      <hardwareInterface>hardware_interface/EffortJointInterface</hardwareInterface>
      <mechanicalReduction>1</mechanicalReduction>
    </actuator>
  </transmission> -->
  <gazebo reference="MP_BODY">
    <material>Gazebo/Orange</material>
  </gazebo>
  <gazebo reference="coxa_lm">
    <material>Gazebo/Black</material>
  </gazebo>
  <gazebo reference="c2_lm">
    <material>Gazebo/Orange</material>
  </gazebo>
  <gazebo reference="femur_lm">
    <material>Gazebo/Black</material>
  </gazebo>
  <gazebo reference="tibia_lm">
    <material>Gazebo/Orange</material>
  </gazebo>
  <link name="coxa_lr">
    <inertial>
      <origin rpy="0 0 0" xyz="0 0 0"/>
      <mass value="0.024357719"/>
      <inertia ixx="0.0051411124" ixy="-0.00057530255" ixz="-0.000024729049" iyy="0.0081915737" iyz="-0.000019223094" izz="0.0011379812"/>
    </inertial>
    <visual>
      <origin rpy="0 0 0" xyz="0 0 0"/>
      <geometry>
        <box size="0.022 0.045 0.0325"/>
        <!--<mesh filename="package://phantomx_description/meshes/connect.STL"  scale="1 1 1"/>-->
      </geometry>
      <material name="Grey">
        <color rgba="0.20 0.20 0.20 1.0"/>
      </material>
    </visual>
    <collision>
      <origin rpy="0 0 0" xyz="0 0 0"/>
      <geometry>
        <box size="0.022 0.045 0.0325"/>
        <!-- <mesh filename="package://phantomx_description/meshes/connect_coll.STL"  scale="1 1 1"/> -->
      </geometry>
    </collision>
  </link>
  <link name="c2_lr">
    <inertial>
      <origin rpy="0 0 0" xyz="0 0 0"/>
      <mass value="0.024357719"/>
      <inertia ixx="0.0051411124" ixy="-0.00057530255" ixz="-0.000024729049" iyy="0.0081915737" iyz="-0.000019223094" izz="0.0011379812"/>
    </inertial>
    <visual>
      <origin rpy="0 0 0" xyz="0 0 0"/>
      <geometry>
        <box size="0.005 0.0325 0.0325"/>
        <!-- <mesh filename="package://phantomx_description/meshes/connect.STL"  scale="1 1 1"/>-->
      </geometry>
      <material name="Orange">
        <color rgba="12 12 12 1.0"/>
      </material>
    </visual>
    <collision>
      <origin rpy="0 0 0" xyz="0 0 0"/>
      <geometry>
        <box size="0.005 0.0325 0.0325"/>
        <!-- <mesh filename="package://phantomx_description/meshes/connect.STL"  scale="1 1 1"/>-->
      </geometry>
    </collision>
  </link>
  <link name="femur_lr">
    <inertial>
      <origin rpy="0 0 0" xyz="1 0 0"/>
      <mass value="0.0286"/>
      <!-- <inertia ixx="0.000035572"  ixy="-0.000114256"  ixz="-0.000008584" iyy="0.000756486" iyz="-0.000001714" izz="0.000791714" /> -->
      <inertia ixx="0.00059" ixy="-0.0" ixz="-0.0" iyy="0.0" iyz="-0.0" izz="0.00059"/>
    </inertial>
    <visual>
      <origin rpy="0 1.57 0" xyz="0.075 0 0"/>
      <geometry>
        <!-- <box size="0.022 0.25 0.0325" /> -->
        <cylinder length="0.15" radius="0.015"/>
        <!--<mesh filename="package://phantomx_description/meshes/thigh_l.STL"  scale="1 1 1"/>-->
      </geometry>
      <material name="Grey">
        <color rgba="0.20 0.20 0.20 1.0"/>
      </material>
    </visual>
    <collision>
      <origin rpy="0 1.57 0" xyz="0.075 0 0"/>
      <geometry>
        <cylinder length="0.15" radius="0.015"/>
        <!-- <mesh filename="package://phantomx_description/meshes/thigh_l_coll.STL"  scale="1 1 1"/> -->
      </geometry>
    </collision>
  </link>
  <link name="tibia_lr">
    <inertial>
      <origin rpy="0 0 0" xyz="0 0 0"/>
      <mass value="0.0286"/>
      <!-- g/mm^2 -->
      <!-- <inertia ixx="35572"  ixy="-114256"  ixz="-8584" iyy="756486" iyz="-1714" izz="791714" /> -->
      <!-- <inertia ixx="0.000035572"  ixy="-0.000114256"  ixz="-0.000008584" iyy="0.000756486" iyz="-0.000001714" izz="0.000791714" /> -->
      <inertia ixx="0.00059" ixy="-0.0" ixz="-0.0" iyy="0.0" iyz="-0.0" izz="0.00059"/>
    </inertial>
    <visual>
      <origin rpy="1.57 0 1.57" xyz="0.125 0 0"/>
      <geometry>
        <cylinder length="0.25" radius="0.015"/>
        <!-- <box size="0.022 0.25 0.0325" /> -->
        <!--<mesh filename="package://phantomx_description/meshes/tibia_l.STL"  scale="1 1 1"/>-->
      </geometry>
      <material name="Orange">
        <color rgba="12 12 12 1.0"/>
      </material>
    </visual>
    <collision>
      <origin rpy="1.57 0 1.57" xyz="0.125 0 0"/>
      <geometry>
        <cylinder length="0.25" radius="0.015"/>
        <!-- <mesh filename="package://phantomx_description/meshes/tibia_l_coll.STL"  scale="1 1 1"/> -->
      </geometry>
    </collision>
  </link>
  <joint name="j_coxa_lr" type="revolute">
    <parent link="MP_BODY"/>
    <child link="coxa_lr"/>
    <origin rpy="0 0 2.62" xyz="-0.175 0.1  0.001116"/>
    <axis xyz="0 0 1"/>
    <limit effort="30" lower="-3.14" upper="3.14" velocity="0.5"/>
  </joint>
  <joint name="j_c2_lr" type="fixed">
    <parent link="coxa_lr"/>
    <child link="c2_lr"/>
    <origin rpy="0 0 0" xyz="0.0135 0 0"/>
    <limit effort="30" lower="-3.14" upper="3.14" velocity="0.5"/>
  </joint>
  <joint name="j_femur_lr" type="revolute">
    <parent link="c2_lr"/>
    <child link="femur_lr"/>
    <origin rpy=" 1.57 0 0" xyz="0 0 0"/>
    <axis xyz="0 0 1"/>
    <limit effort="30" lower="-3.14" upper="3.14" velocity="0.5"/>
  </joint>
  <joint name="j_tibia_lr" type="revolute">
    <parent link="femur_lr"/>
    <child link="tibia_lr"/>
    <origin rpy="0 0 0" xyz="0.125 0 0"/>
    <axis xyz="0 0 1"/>
    <limit effort="30" lower="-3.14" upper="3.14" velocity="0.5"/>
  </joint>
  <!-- <gazebo reference="$tibia_${suffix}">
        <mu1>1</mu1>
        <mu2>1</mu2>
        <fdir1>1 0 0</fdir1>
        <minDepth>0.005</minDepth>
        <maxContacts>1</maxContacts>
            <collision name="$tibia_${suffix}_collision">
                <geometry>
                    <sphere>
                    <radius>0.02175</radius>
                </sphere>
                </geometry>

            <surface>
                <friction>
                    <torsional>
                            <coefficient>10</coefficient>
                            <use_patch_radius>true</use_patch_radius>
                            <surface_radius>0.05</surface_radius>
                            <patch_radius>0.01</patch_radius>
                    </torsional>
            </friction>
            <contact>
                <poissons_ratio>0.5</poissons_ratio>
                <elastic_modulus>1e8</elastic_modulus>
            </contact>
        </surface>
    </collision>
    </gazebo> -->
  <!-- <joint name="j_coxa_${suffix}" type="revolute">
    <parent link="MP_BODY"/>
    <child link="coxa_${suffix}"/>
    <origin xyz="${xyz}" rpy="${rpy}" />
    <axis xyz="1 0 0" />
    <limit effort="2.8" velocity="5.6548668" lower="-2.6179939" upper="2.6179939" />
  </joint>

  <joint name="j_c2_${suffix}" type="fixed">
    <parent link="coxa_${suffix}"/>
    <child link="c2_${suffix}"/>
    <origin xyz="0 -0.033 0" rpy="0 1.5704 3.14159" />
  </joint>


  <joint name="j_femur_${suffix}" type="revolute">
    <parent link="c2_${suffix}"/>
    <child link="femur_${suffix}"/>
    <origin xyz="0 0.117 0" rpy=" -1.5707 0 3.14159" />
    <axis xyz="1 0 0" />
    <limit effort="2.8" velocity="5.6548668" lower="-2.6179939" upper="2.6179939" />
  </joint>

  <joint name="j_tibia_${suffix}" type="revolute">
    <parent link="femur_${suffix}"/>
    <child link="tibia_${suffix}"/>
    <origin xyz="0 ${femur_offset_y} ${femur_offset_z}" rpy="-1.5707 0 3.14159" />
    <axis xyz="1 0 0" />
    <limit effort="2.8" velocity="5.6548668" lower="-2.6179939" upper="2.6179939" />
  </joint> -->
  <transmission name="t_coxa_lr" type="ardent_model/SimpleTransmission">
    <joint name="j_coxa_lr"/>
    <actuator name="j_coxa_lr_motor"/>
    <mechanicalReduction>1</mechanicalReduction>
    <!-- <compensator k_belt="4000.0" mass_motor="0.05" kd_motor="15.0" lambda_motor="40.0" lambda_joint="40.0" lambda_combined="0.0"/> -->
  </transmission>
  <transmission name="t_femur_lr" type="ardent_model/SimpleTransmission">
    <joint name="j_femur_lr"/>
    <actuator name="j_femur_lr_motor"/>
    <mechanicalReduction>1</mechanicalReduction>
    <!-- <compensator k_belt="4000.0" mass_motor="0.05" kd_motor="15.0" lambda_motor="40.0" lambda_joint="40.0" lambda_combined="0.0"/> -->
  </transmission>
  <transmission name="t_tibia_lr" type="ardent_model/SimpleTransmission">
    <joint name="j_tibia_lr"/>
    <actuator name="j_tibia_lr_motor"/>
    <mechanicalReduction>1</mechanicalReduction>
    <!-- <compensator k_belt="4000.0" mass_motor="0.05" kd_motor="15.0" lambda_motor="40.0" lambda_joint="40.0" lambda_combined="0.0"/> -->
  </transmission>
  <!-- <transmission name="t_coxa_${suffix}">
    <type>transmission_interface/SimpleTransmission</type>
    <joint name="j_coxa_${suffix}">
      <hardwareInterface>hardware_interface/EffortJointInterface</hardwareInterface>    
    </joint>
    <actuator name="m_coxa_${suffix}">
      <hardwareInterface>hardware_interface/EffortJointInterface</hardwareInterface>
      <mechanicalReduction>1</mechanicalReduction>
    </actuator>
  </transmission>


   <transmission name="t_femur_${suffix}">
    <type>transmission_interface/SimpleTransmission</type>
    <joint name="j_femur_${suffix}">
      <hardwareInterface>hardware_interface/EffortJointInterface</hardwareInterface>    
    </joint>
    <actuator name="m_femur_${suffix}">
      <hardwareInterface>hardware_interface/EffortJointInterface</hardwareInterface>
      <mechanicalReduction>1</mechanicalReduction>
    </actuator>
  </transmission>


   <transmission name="t_tibia_${suffix}">
    <type>transmission_interface/SimpleTransmission</type>
    <joint name="j_tibia_${suffix}">
      <hardwareInterface>hardware_interface/EffortJointInterface</hardwareInterface>
    </joint>
    <actuator name="m_tibia_${suffix}">
      <hardwareInterface>hardware_interface/EffortJointInterface</hardwareInterface>
      <mechanicalReduction>1</mechanicalReduction>
    </actuator>
  </transmission> -->
  <gazebo reference="MP_BODY">
    <material>Gazebo/Orange</material>
  </gazebo>
  <gazebo reference="coxa_lr">
    <material>Gazebo/Black</material>
  </gazebo>
  <gazebo reference="c2_lr">
    <material>Gazebo/Orange</material>
  </gazebo>
  <gazebo reference="femur_lr">
    <material>Gazebo/Black</material>
  </gazebo>
  <gazebo reference="tibia_lr">
    <material>Gazebo/Orange</material>
  </gazebo>
  <gazebo>
    <plugin filename="libgazebo_ros_control.so" name="gazebo_ros_control">
      <!-- <robotNamespace>/ardent</robotNamespace> -->
    </plugin>
  </gazebo>
</robot>

